Workbook

Sheet Como usar
A1: Como usar
A3: Primeira vez (Google Sheets)
A4: 1. Arquivo → Importar → envie este .xlsx → 'Criar nova planilha'.
A5: 2. Extensões → Apps Script → apague o código, cole o conteúdo de Lunaris.gs, salve. Recarregue a planilha.
A6: 3. Menu Genshin → 'Aplicar caixas de seleção e listas' (autorize). Depois Genshin → 'Atualizar dados do Lunaris'.
A7: 4. Opcional: Genshin → 'Atualizar automaticamente todo dia'.
A8: 5. Para as listas virarem 'chips': selecione a célula → Dados → Validação de dados → Avançado → Estilo de exibição: Chip.
A10: Uso normal
A11: • Time: personagem, arma, sets, main stats, raridade de cada peça (caixa marcada = 5★) e nível dos talentos.
A12: • Rotação: uma linha por golpe — a lista mostra só os golpes dos 4 do time (+ Golpes extras).
A13: • Perfis de buff: cada linha da Rotação escolhe um perfil (Todos, Nenhum ou um que você monta) dizendo quais buffs do
A14: time ainda estão ativos naquele trecho (ex.: depois que o Supremo da Iansan acaba).
... A28: • Taxa/dano crit extras valem para a rotação inteira.

Sheet Time
A1: Time e configurações
A2: Amarelo = você escolhe. Caixa marcada em '5★?' = peça 5 estrelas; desmarcada = 4 estrelas.
B3: Slot 1 | C3: Slot 2 | D3: Slot 3 | E3: Slot 4
A4: Personagem | B4: Mavuika | C4: Citlali | D4: Iansan | E4: Bennett
A5: Arma | B5: A Thousand Blazing Suns | C5: Thrilling Tales of Dragon Slayers | D5: Engulfing Lightning | E5: Absolution
A6: Set principal (4 peças) | B6: Obsidian Codex | C6: Instructor | D6: Scroll of the Hero of Cinder City | E6: Noblesse Oblige
A7: Set secundário (opcional → vira 2+2)
A8: Areia (main) | B8: EM | C8: ER | D8: ATK% | E8: ER
A9: Cálice (main) | B9: DMG% elemental | C9: DMG% elemental | D9: ATK% | E9: DMG% elemental
A10: Tiara (main) | B10: CD | C10: CR | D10: CR | E10: CR
A11: Flor 5★? | B11: TRUE | C11: FALSE | D11: TRUE | E11: TRUE
A12: Pena 5★? | B12: TRUE | C12: FALSE | D12: TRUE | E12: TRUE
A13: Areia 5★? | B13: TRUE | C13: TRUE | D13: TRUE | E13: TRUE
A14: Cálice 5★? | B14: TRUE | C14: FALSE | D14: TRUE | E14: TRUE
A15: Tiara 5★? | B15: TRUE | C15: FALSE | D15: TRUE | E15: TRUE
A16: Nível do talento: Ataque normal | B16: 10 | C16: 10 | D16: 10 | E16: 10
A17: Nível do talento: Habilidade | B17: 10 | C17: 10 | D17: 13 | E17: 13
A18: Nível do talento: Supremo | B18: 10 | C18: 10 | D18: 13 | E18: 13
A19: ER mínimo desejado | B19: 1 | C19: 2 | D19: 2 | E19: 2
A20: Rolls totais (vazio = automático) | B20: 40 | C20: 40 | D20: 40 | E20: 40
A21: Rolls em crítico CR+CD (vazio = otimizar) | B21: 20
A22: Configurações gerais | B22: Valor
A23: Nível dos personagens | B23: 90
A24: Nível do inimigo | B24: 100
A25: RES base do inimigo | B25: 0.1
A26: Redução de DEF do inimigo | B26: 0
A27: Rolls mínimos em cada substatus | B27: 2
A28: Duração da rotação (s) | B28: 17.5
A30: Buffs extras (o que não vem automático de personagem/arma/set)
A31: Alvo (personagem ou Todos) | B31: Stat | C31: Valor | D31: É buff do time? (segue o perfil) | E31: Descrição | F31: Rótulo (perfis de buff) | G31: (auxiliar)
A32: Mavuika | B32: ATK% | C32: 0.48 | D32: Sim | E32: TTDS R5 da Citlali (10 s após a troca em 6,7 s) | F32: TTDS | G32: =IF(F32="","_geral",TRIM(F32)) -> TTDS
A33: Mavuika | B33: DMG% | C33: 0.4 | D33: Sim | E33: Scroll da Iansan (12% + 28% Nightsoul) — Pyro/Electro | F33: Scroll | G33: =IF(F33="","_geral",TRIM(F33)) -> Scroll
A34: Bennett | B34: DMG% | C34: 0.4 | D34: Sim | E34: Scroll da Iansan | F34: Scroll | G34: =IF(F34="","_geral",TRIM(F34)) -> Scroll
A35: Iansan | B35: DMG% | C35: 0.4 | D35: Sim | E35: Scroll da Iansan (depois da reação dela) | F35: Scroll | G35: =IF(F35="","_geral",TRIM(F35)) -> Scroll
A36: Mavuika | B36: ATK% | C36: 0.3 | D36: Não | E36: Da planilha original — origem não identificada, confirme | G36: =IF(F36="","_geral",TRIM(F36)) -> _geral
A37: Mavuika | B37: DMG% | C37: 0.25 | D37: Não | E37: Da planilha original — origem não identificada, confirme | G37: =IF(F37="","_geral",TRIM(F37)) -> _geral
A38: Mavuika | B38: DMG% | C38: 0.15 | D38: Não | E38: Da planilha original — origem não identificada, confirme | G38: =IF(F38="","_geral",TRIM(F38)) -> _geral
A39: Citlali | B39: ATK% | C39: 0.3 | D39: Não | E39: Da planilha original — origem não identificada, confirme | G39: =IF(F39="","_geral",TRIM(F39)) -> _geral
D40: Não | G40: =IF(F40="","_geral",TRIM(F40)) -> _geral
D41: Não | G41: =IF(F41="","_geral",TRIM(F41)) -> _geral
...

Sheet Rotação
A1: Rotação
A2: Preencha só A–E. A lista de golpes mostra os golpes dos 4 do time + os 'Golpes extras'. Desmarque 'Buffs do time' quando os buffs já acabaram.
A4: Golpe | B4: Hits | C4: Reação | D4: Perfil de buffs | E4: Ajuste DMG% (linha) | F4: Golpe extra? | G4: Golpe base | H4: Linha em L_Golpes | I4: Personagem | J4: Slot | K4: Tipo | L4: Talento | M4: Nível | N4: Escala ATK | O4: Escala EM | P4: Escala HP | Q4: Escala DEF | R4: Elemento | S4: Reação efetiva | T4: Perfil (efetivo) | U4: DMG% total | V4: Mult. DEF | W4: Mult. RES | X4: Fator (hits×DMG×DEF×RES) | Y4: Fator × ATK | Z4: Fator × EM | AA4: Fator × HP | AB4: Fator × DEF | AC4: ATK usado | AD4: EM usada | AE4: HP usado | AF4: DEF usada | AG4: Mult. reação | AH4: Dano (sem crit) | AI4: Dano (crit) | AJ4: Dano (média) | AK4: Dano fixo recebido (soma) | AL4: Fator dano fixo | AN4: Notas (livre)
A5: Mavuika - Habilidade: Flamestrider Charged Attack Cyclic DMG | B5: 1 | C5: Derreter | D5: Todos | E5: -0.4 | F5: =IF($A5="","",IF(ISNUMBER(MATCH($A5,'Golpes extras'!$A$2:$A$101,0)),"Sim","Não")) -> Não | G5: {=IF($A5="","",IF($F5="Sim",INDEX('Golpes extras'!$B$2:$B$101,MATCH($A5,'Golpes extras'!$A$2:$A$101,0))&"",$A5))} -> Mavuika - Habilidade: Flamestrider Charged Attack Cyclic DMG | H5: =IF($G5="","",IFERROR(MATCH($G5,L_Golpes!$A$2:$A$6000,0),"")) -> 52 | I5: {=IF($A5="","",IF(ISNUMBER($H5),INDEX(L_Golpes!$B$2:$B$6000,$H5),IF(IFERROR(INDEX('Golpes extras'!$C$2:$C$101,MATCH($A5,'Golpes extras'!$A$2:$A$101,0))&"","")<>"",INDEX('Golpes extras'!$C$2:$C$101,MATCH($A5,'Golpes extras'!$A$2:$A$101,0))&"","golpe?")))} -> Mavuika | J5: =IF(OR($I5="",$I5="golpe?"),"",IFERROR(MATCH($I5,Time!$B$4:$E$4,0),"fora do time")) -> 1 | K5: {=IF(ISNUMBER($J5),IF(IFERROR(INDEX('Golpes extras'!$D$2:$D$101,MATCH($A5,'Golpes extras'!$A$2:$A$101,0))&"","")<>"",INDEX('Golpes extras'!$D$2:$D$101,MATCH($A5,'Golpes extras'!$A$2:$A$101,0))&"",IF(ISNUMBER($H5),INDEX(L_Golpes!$D$2:$D$6000,$H5),"Outro")),"")} -> Carregado | L5: {=IF(ISNUMBER($J5),IF(ISNUMBER($H5),INDEX(L_Golpes!$C$2:$C$6000,$H5),""),"")} -> Habilidade | M5: {=IF(ISNUMBER($J5),IF($L5="Normal",INDEX('Cálculos'!$C$14:$F$14,$J5),IF($L5="Habilidade",INDEX('Cálculos'!$C$15:$F$15,$J5),IF($L5="Supremo",INDEX('Cálculos'!$C$16:$F$16,$J5),""))),"")} -> 10 | N5: {=IF(ISNUMBER($J5),IF(ISNUMBER($H5),INDEX(L_Golpes!$F$2:$T$6000,$H5,MAX(1,MIN(15,$M5))),0)+IF($F5="Sim",N(INDEX('Golpes extras'!$E$2:$E$101,MATCH($A5,'Golpes extras'!$A$2:$A$101,0))),0),"")} -> 1.955 | O5: {=IF(ISNUMBER($J5),IF(ISNUMBER($H5),INDEX(L_Golpes!$U$2:$AI$6000,$H5,MAX(1,MIN(15,$M5))),0)+IF($F5="Sim",N(INDEX('Golpes extras'!$F$2:$F$101,MATCH($A5,'Golpes extras'!$A$2:$A$101,0))),0),"")} -> 0 | P5: {=IF(ISNUMBER($J5),IF(ISNUMBER($H5),INDEX(L_Golpes!$AJ$2:$AX$6000,$H5,MAX(1,MIN(15,$M5))),0)+IF($F5="Sim",N(INDEX('Golpes extras'!$G$2:$G$101,MATCH($A5,'Golpes extras'!$A$2:$A$101,0))),0),"")} -> 0 | Q5: {=IF(ISNUMBER($J5),IF(ISNUMBER($H5),INDEX(L_Golpes!$AY$2:$BM$6000,$H5,MAX(1,MIN(15,$M5))),0)+IF($F5="Sim",N(INDEX('Golpes extras'!$H$2:$H$101,MATCH($A5,'Golpes extras'!$A$2:$A$101,0))),0),"")} -> 0 | R5: {=IF(ISNUMBER($J5),INDEX('Cálculos'!$C$19:$F$19,$J5),"")} -> Pyro | S5: =IF(ISNUMBER($J5),IF(AND($C5="Derreter",OR($R5="Pyro",$R5="Cryo")),"Derreter",IF(AND($C5="Vaporizar",OR($R5="Pyro",$R5="Hydro")),"Vaporizar","Nenhuma")),"") -> Derreter | T5: =IF(ISNUMBER($J5),IF(OR($D5="Não",$D5=FALSE),'Perfis de buff'!$A$8,IF(OR($D5="",$D5="Sim",$D5=TRUE),'Perfis de buff'!$A$4,$D5)),"") -> Todos | U5: {=IF(ISNUMBER($J5),INDEX('Cálculos'!$C$113:$F$113,$J5)+IF($K5="Normal",INDEX('Cálculos'!$C$114:$F$114,$J5),IF($K5="Carregado",INDEX('Cálculos'!$C$115:$F$115,$J5),IF($K5="Habilidade",INDEX('Cálculos'!$C$116:$F$116,$J5),IF($K5="Supremo",INDEX('Cálculos'!$C$117:$F$117,$J5),0))))+INDEX('Cálculos'!$C$143:$F$147,IFERROR(MATCH($T5,'Perfis de buff'!$A$4:$A$8,0),1),$J5)+IF($K5="Normal",INDEX('Cálculos'!$C$148:$F$152,IFERROR(MATCH($T5,'Perfis de buff'!$A$4:$A$8,0),1),$J5),IF($K5="Carregado",INDEX('Cálculos'!$C$153:$F$157,IFERROR(MATCH($T5,'Perfis de buff'!$A$4:$A$8,0),1),$J5),IF($K5="Habilidade",INDEX('Cálculos'!$C$158:$F$162,IFERROR(MATCH($T5,'Perfis de buff'!$A$4:$A$8,0),1),$J5),IF($K5="Supremo",INDEX('Cálculos'!$C$163:$F$167,IFERROR(MATCH($T5,'Perfis de buff'!$A$4:$A$8,0),1),$J5),0))))+N($E5),"")} -> 1.416 | V5: {=IF(ISNUMBER($J5),INDEX('Cálculos'!$C$180:$F$180,$J5),"")} -> 0.48717949 | W5: {=IF(ISNUMBER($J5),INDEX('Cálculos'!$C$182:$F$182,$J5),"")} -> 1.05 | X5: =IF(ISNUMBER($J5),IF($B5="",1,$B5)*(1+$U5)*$V5*$W5,"") -> 1.2358769 | Y5: =IF(ISNUMBER($J5),$X5*$N5,"") -> 2.4161394 | Z5: =IF(ISNUMBER($J5),$X5*$O5,"") -> 0 | AA5: =IF(ISNUMBER($J5),$X5*$P5,"") -> 0 | AB5: =IF(ISNUMBER($J5),$X5*$Q5,"") -> 0 | AC5: {=IF(ISNUMBER($J5),INDEX('Cálculos'!$C$332:$F$336,IFERROR(MATCH($T5,'Perfis de buff'!$A$4:$A$8,0),1),$J5),"")} -> 5791.25 | AD5: {=IF(ISNUMBER($J5),INDEX('Cálculos'!$C$339:$F$343,IFERROR(MATCH($T5,'Perfis de buff'!$A$4:$A$8,0),1),$J5),"")} -> 424 | AE5: {=IF(ISNUMBER($J5),INDEX('Cálculos'!$C$337:$F$337,$J5),"")} -> 19082.648 | AF5: {=IF(ISNUMBER($J5),INDEX('Cálculos'!$C$338:$F$338,$J5),"")} -> 929.208 | AG5: {=IF(ISNUMBER($J5),IF($S5="Derreter",INDEX('Cálculos'!$C$124:$F$124,$J5)*(1+2.78*$AD5/($AD5+1400)+INDEX('Cálculos'!$C$122:$F$122,$J5)),IF($S5="Vaporizar",INDEX('Cálculos'!$C$125:$F$125,$J5)*(1+2.78*$AD5/($AD5+1400)+INDEX('Cálculos'!$C$123:$F$123,$J5)),1)),"")} -> 3.2924561 | AH5: =IF(ISNUMBER($J5),(($AC5*$N5+$AD5*$O5+$AE5*$P5+$AF5*$Q5)*$X5+$AL5)*$AG5,"") -> 46069.585 | AI5: {=IF(ISNUMBER($J5),$AH5*(1+INDEX('Cálculos'!$C$331:$F$331,$J5)),"")} -> 152858.88 | AJ5: {=IF(ISNUMBER($J5),$AH5*(1+MIN(INDEX('Cálculos'!$C$330:$F$330,$J5),1)*INDEX('Cálculos'!$C$331:$F$331,$J5)),"")} -> 151684.2 | AK5: =IF(ISNUMBER($J5),'Fixo (cálculo)'!$AF5,"") -> 0 | AL5: =IF(ISNUMBER($J5),$AK5*(1+$U5)*$V5*$W5,"") -> 0 | AN5: C 6,9 s — antes do Q (sem Fighting Spirit, sem A4)
A6: Mavuika - Supremo (200 FS) | B6: 1 | C6: Derreter | D6: Todos | E6: -0.012 | F6: =IF($A6="","",IF(ISNUMBER(MATCH($A6,'Golpes extras'!$A$2:$A$101,0)),"Sim","Não")) -> Sim | G6: {=IF($A6="","",IF($F6="Sim",INDEX('Golpes extras'!$B$2:$B$101,MATCH($A6,'Golpes extras'!$A$2:$A$101,0))&"",$A6))} -> Mavuika - Supremo: Skill DMG | H6: =IF($G6="","",IFERROR(MATCH($G6,L_Golpes!$A$2:$A$6000,0),"")) -> 55 | I6: {=IF($A6="","",IF(ISNUMBER($H6),INDEX(L_Golpes!$B$2:$B$6000,$H6),IF(IFERROR(INDEX('Golpes extras'!$C$2:$C$101,MATCH($A6,'Golpes extras'!$A$2:$A$101,0))&"","")<>"",INDEX('Golpes extras'!$C$2:$C$101,MATCH($A6,'Golpes extras'!$A$2:$A$101,0))&"","golpe?")))} -> Mavuika | J6: =IF(OR($I6="",$I6="golpe?"),"",IFERROR(MATCH($I6,Time!$B$4:$E$4,0),"fora do time")) -> 1 | K6: {=IF(ISNUMBER($J6),IF(IFERROR(INDEX('Golpes extras'!$D$2:$D$101,MATCH($A6,'Golpes extras'!$A$2:$A$101,0))&"","")<>"",INDEX('Golpes extras'!$D$2:$D$101,MATCH($A6,'Golpes extras'!$A$2:$A$101,0))&"",IF(ISNUMBER($H6),INDEX(L_Golpes!$D$2:$D$6000,$H6),"Outro")),"")} -> Supremo | L6: {=IF(ISNUMBER($J6),IF(ISNUMBER($H6),INDEX(L_Golpes!$C$2:$C$6000,$H6),""),"")} -> Supremo | M6: {=IF(ISNUMBER($J6),IF($L6="Normal",INDEX('Cálculos'!$C$14:$F$14,$J6),IF($L6="Habilidade",INDEX('Cálculos'!$C$15:$F$15,$J6),IF($L6="Supremo",INDEX('Cálculos'!$C$16:$F$16,$J6),""))),"")} -> 10 | N6: {=IF(ISNUMBER($J6),IF(ISNUMBER($H6),INDEX(L_Golpes!$F$2:$T$6000,$H6,MAX(1,MIN(15,$M6))),0)+IF($F6="Sim",N(INDEX('Golpes extras'!$E$2:$E$101,MATCH($A6,'Golpes extras'!$A$2:$A$101,0))),0),"")} -> 13.7664 | O6: {=IF(ISNUMBER($J6),IF(ISNUMBER($H6),INDEX(L_Golpes!$U$2:$AI$6000,$H6,MAX(1,MIN(15,$M6))),0)+IF($F6="Sim",N(INDEX('Golpes extras'!$F$2:$F$101,MATCH($A6,'Golpes extras'!$A$2:$A$101,0))),0),"")} -> 0 | P6: {=IF(ISNUMBER($J6),IF(ISNUMBER($H6),INDEX(L_Golpes!$AJ$2:$AX$6000,$H6,MAX(1,MIN(15,$M6))),0)+IF($F6="Sim",N(INDEX('Golpes extras'!$G$2:$G$101,MATCH($A6,'Golpes extras'!$A$2:$A$101,0))),0),"")} -> 0 | Q6: {=IF(ISNUMBER($J6),IF(ISNUMBER($H6),INDEX(L_Golpes!$AY$2:$BM$6000,$H6,MAX(1,MIN(15,$M6))),0)+IF($F6="Sim",N(INDEX('Golpes extras'!$H$2:$H$101,MATCH($A6,'Golpes extras'!$A$2:$A$101,0))),0),"")} -> 0 | R6: {=IF(ISNUMBER($J6),INDEX('Cálculos'!$C$19:$F$19,$J6),"")} -> Pyro | S6: =IF(ISNUMBER($J6),IF(AND($C6="Derreter",OR($R6="Pyro",$R6="Cryo")),"Derreter",IF(AND($C6="Vaporizar",OR($R6="Pyro",$R6="Hydro")),"Vaporizar","Nenhuma")),"") -> Derreter | T6: =IF(ISNUMBER($J6),IF(OR($D6="Não",$D6=FALSE),'Perfis de buff'!$A$8,IF(OR($D6="",$D6="Sim",$D6=TRUE),'Perfis de buff'!$A$4,$D6)),"") -> Todos | U6: {=IF(ISNUMBER($J6),INDEX('Cálculos'!$C$113:$F$113,$J6)+IF($K6="Normal",INDEX('Cálculos'!$C$114:$F$114,$J6),IF($K6="Carregado",INDEX('Cálculos'!$C$115:$F$115,$J6),IF($K6="Habilidade",INDEX('Cálculos'!$C$116:$F$116,$J6),IF($K6="Supremo",INDEX('Cálculos'!$C$117:$F$117,$J6),0))))+INDEX('Cálculos'!$C$143:$F$147,IFERROR(MATCH($T6,'Perfis de buff'!$A$4:$A$8,0),1),$J6)+IF($K6="Normal",INDEX('Cálculos'!$C$148:$F$152,IFERROR(MATCH($T6,'Perfis de buff'!$A$4:$A$8,0),1),$J6),IF($K6="Carregado",INDEX('Cálculos'!$C$153:$F$157,IFERROR(MATCH($T6,'Perfis de buff'!$A$4:$A$8,0),1),$J6),IF($K6="Habilidade",INDEX('Cálculos'!$C$158:$F$162,IFERROR(MATCH($T6,'Perfis de buff'!$A$4:$A$8,0),1),$J6),IF($K6="Supremo",INDEX('Cálculos'!$C$163:$F$167,IFERROR(MATCH($T6,'Perfis de buff'!$A$4:$A$8,0),1),$J6),0))))+N($E6),"")} -> 1.804 | V6: {=IF(ISNUMBER($J6),INDEX('Cálculos'!$C$180:$F$180,$J6),"")} -> 0.48717949 | W6: {=IF(ISNUMBER($J6),INDEX('Cálculos'!$C$182:$F$182,$J6),"")} -> 1.05 | X6: =IF(ISNUMBER($J6),IF($B6="",1,$B6)*(1+$U6)*$V6*$W6,"") -> 1.4343538 | Y6: =IF(ISNUMBER($J6),$X6*$N6,"") -> 19.745889 | Z6: =IF(ISNUMBER($J6),$X6*$O6,"") -> 0 | AA6: =IF(ISNUMBER($J6),$X6*$P6,"") -> 0 | AB6: =IF(ISNUMBER($J6),$X6*$Q6,"") -> 0 | AC6: {=IF(ISNUMBER($J6),INDEX('Cálculos'!$C$332:$F$336,IFERROR(MATCH($T6,'Perfis de buff'!$A$4:$A$8,0),1),$J6),"")} -> 5791.25 | AD6: {=IF(ISNUMBER($J6),INDEX('Cálculos'!$C$339:$F$343,IFERROR(MATCH($T6,'Perfis de buff'!$A$4:$A$8,0),1),$J6),"")} -> 424 | AE6: {=IF(ISNUMBER($J6),INDEX('Cálculos'!$C$337:$F$337,$J6),"")} -> 19082.648 | AF6: {=IF(ISNUMBER($J6),INDEX('Cálculos'!$C$338:$F$338,$J6),"")} -> 929.208 | AG6: {=IF(ISNUMBER($J6),IF($S6="Derreter",INDEX('Cálculos'!$C$124:$F$124,$J6)*(1+2.78*$AD6/($AD6+1400)+INDEX('Cálculos'!$C$122:$F$122,$J6)),IF($S6="Vaporizar",INDEX('Cálculos'!$C$125:$F$125,$J6)*(1+2.78*$AD6/($AD6+1400)+INDEX('Cálculos'!$C$123:$F$123,$J6)),1)),"")} -> 3.2924561 | AH6: =IF(ISNUMBER($J6),(($AC6*$N6+$AD6*$O6+$AE6*$P6+$AF6*$Q6)*$X6+$AL6)*$AG6,"") -> 376503.48 | AI6: {=IF(ISNUMBER($J6),$AH6*(1+INDEX('Cálculos'!$C$331:$F$331,$J6)),"")} -> 1249238.6 | AJ6: {=IF(ISNUMBER($J6),$AH6*(1+MIN(INDEX('Cálculos'!$C$330:$F$330,$J6),1)*INDEX('Cálculos'!$C$331:$F$331,$J6)),"")} -> 1239638.5 | AK6: =IF(ISNUMBER($J6),'Fixo (cálculo)'!$AF6,"") -> 0 | AL6: =IF(ISNUMBER($J6),$AK6*(1+$U6)*$V6*$W6,"") -> 0 | AN6: 8.0 s · Q 7,4 s
A7: Mavuika - Carregado no Supremo | B7: 1 | C7: Nenhuma | D7: Todos | E7: -0.016 | F7: =IF($A7="","",IF(ISNUMBER(MATCH($A7,'Golpes extras'!$A$2:$A$101,0)),"Sim","Não")) -> Sim | G7: {=IF($A7="","",IF($F7="Sim",INDEX('Golpes extras'!$B$2:$B$101,MATCH($A7,'Golpes extras'!$A$2:$A$101,0))&"",$A7))} -> Mavuika - Habilidade: Flamestrider Charged Attack Cyclic DMG | H7: =IF($G7="","",IFERROR(MATCH($G7,L_Golpes!$A$2:$A$6000,0),"")) -> 52 | I7: {=IF($A7="","",IF(ISNUMBER($H7),INDEX(L_Golpes!$B$2:$B$6000,$H7),IF(IFERROR(INDEX('Golpes extras'!$C$2:$C$101,MATCH($A7,'Golpes extras'!$A$2:$A$101,0))&"","")<>"",INDEX('Golpes extras'!$C$2:$C$101,MATCH($A7,'Golpes extras'!$A$2:$A$101,0))&"","golpe?")))} -> Mavuika | J7: =IF(OR($I7="",$I7="golpe?"),"",IFERROR(MATCH($I7,Time!$B$4:$E$4,0),"fora do time")) -> 1 | K7: {=IF(ISNUMBER($J7),IF(IFERROR(INDEX('Golpes extras'!$D$2:$D$101,MATCH($A7,'Golpes extras'!$A$2:$A$101,0))&"","")<>"",INDEX('Golpes extras'!$D$2:$D$101,MATCH($A7,'Golpes extras'!$A$2:$A$101,0))&"",IF(ISNUMBER($H7),INDEX(L_Golpes!$D$2:$D$6000,$H7),"Outro")),"")} -> Carregado | L7: {=IF(ISNUMBER($J7),IF(ISNUMBER($H7),INDEX(L_Golpes!$C$2:$C$6000,$H7),""),"")} -> Habilidade | M7: {=IF(ISNUMBER($J7),IF($L7="Normal",INDEX('Cálculos'!$C$14:$F$14,$J7),IF($L7="Habilidade",INDEX('Cálculos'!$C$15:$F$15,$J7),IF($L7="Supremo",INDEX('Cálculos'!$C$16:$F$16,$J7),""))),"")} -> 10 | N7: {=IF(ISNUMBER($J7),IF(ISNUMBER($H7),INDEX(L_Golpes!$F$2:$T$6000,$H7,MAX(1,MIN(15,$M7))),0)+IF($F7="Sim",N(INDEX('Golpes extras'!$E$2:$E$101,MATCH($A7,'Golpes extras'!$A$2:$A$101,0))),0),"")} -> 3.995 | O7: {=IF(ISNUMBER($J7),IF(ISNUMBER($H7),INDEX(L_Golpes!$U$2:$AI$6000,$H7,MAX(1,MIN(15,$M7))),0)+IF($F7="Sim",N(INDEX('Golpes extras'!$F$2:$F$101,MATCH($A7,'Golpes extras'!$A$2:$A$101,0))),0),"")} -> 0 | P7: {=IF(ISNUMBER($J7),IF(ISNUMBER($H7),INDEX(L_Golpes!$AJ$2:$AX$6000,$H7,MAX(1,MIN(15,$M7))),0)+IF($F7="Sim",N(INDEX('Golpes extras'!$G$2:$G$101,MATCH($A7,'Golpes extras'!$A$2:$A$101,0))),0),"")} -> 0 | Q7: {=IF(ISNUMBER($J7),IF(ISNUMBER($H7),INDEX(L_Golpes!$AY$2:$BM$6000,$H7,MAX(1,MIN(15,$M7))),0)+IF($F7="Sim",N(INDEX('Golpes extras'!$H$2:$H$101,MATCH($A7,'Golpes extras'!$A$2:$A$101,0))),0),"")} -> 0 | R7: {=IF(ISNUMBER($J7),INDEX('Cálculos'!$C$19:$F$19,$J7),"")} -> Pyro | S7: =IF(ISNUMBER($J7),IF(AND($C7="Derreter",OR($R7="Pyro",$R7="Cryo")),"Derreter",IF(AND($C7="Vaporizar",OR($R7="Pyro",$R7="Hydro")),"Vaporizar","Nenhuma")),"") -> Nenhuma | T7: =IF(ISNUMBER($J7),IF(OR($D7="Não",$D7=FALSE),'Perfis de buff'!$A$8,IF(OR($D7="",$D7="Sim",$D7=TRUE),'Perfis de buff'!$A$4,$D7)),"") -> Todos | U7: {=IF(ISNUMBER($J7),INDEX('Cálculos'!$C$113:$F$113,$J7)+IF($K7="Normal",INDEX('Cálculos'!$C$114:$F$114,$J7),IF($K7="Carregado",INDEX('Cálculos'!$C$115:$F$115,$J7),IF($K7="Habilidade",INDEX('Cálculos'!$C$116:$F$116,$J7),IF($K7="Supremo",INDEX('Cálculos'!$C$117:$F$117,$J7),0))))+INDEX('Cálculos'!$C$143:$F$147,IFERROR(MATCH($T7,'Perfis de buff'!$A$4:$A$8,0),1),$J7)+IF($K7="Normal",INDEX('Cálculos'!$C$148:$F$152,IFERROR(MATCH($T7,'Perfis de buff'!$A$4:$A$8,0),1),$J7),IF($K7="Carregado",INDEX('Cálculos'!$C$153:$F$157,IFERROR(MATCH($T7,'Perfis de buff'!$A$4:$A$8,0),1),$J7),IF($K7="Habilidade",INDEX('Cálculos'!$C$158:$F$162,IFERROR(MATCH($T7,'Perfis de buff'!$A$4:$A$8,0),1),$J7),IF($K7="Supremo",INDEX('Cálculos'!$C$163:$F$167,IFERROR(MATCH($T7,'Perfis de buff'!$A$4:$A$8,0),1),$J7),0))))+N($E7),"")} -> 1.8 | V7: {=IF(ISNUMBER($J7),INDEX('Cálculos'!$C$180:$F$180,$J7),"")} -> 0.48717949 | W7: {=IF(ISNUMBER($J7),INDEX('Cálculos'!$C$182:$F$182,$J7),"")} -> 1.05 | X7: =IF(ISNUMBER($J7),IF($B7="",1,$B7)*(1+$U7)*$V7*$W7,"") -> 1.4323077 | Y7: =IF(ISNUMBER($J7),$X7*$N7,"") -> 5.7220692 | Z7: =IF(ISNUMBER($J7),$X7*$O7,"") -> 0 | AA7: =IF(ISNUMBER($J7),$X7*$P7,"") -> 0 | AB7: =IF(ISNUMBER($J7),$X7*$Q7,"") -> 0 | AC7: {=IF(ISNUMBER($J7),INDEX('Cálculos'!$C$332:$F$336,IFERROR(MATCH($T7,'Perfis de buff'!$A$4:$A$8,0),1),$J7),"")} -> 5791.25 | AD7: {=IF(ISNUMBER($J7),INDEX('Cálculos'!$C$339:$F$343,IFERROR(MATCH($T7,'Perfis de buff'!$A$4:$A$8,0),1),$J7),"")} -> 424 | AE7: {=IF(ISNUMBER($J7),INDEX('Cálculos'!$C$337:$F$337,$J7),"")} -> 19082.648 | AF7: {=IF(ISNUMBER($J7),INDEX('Cálculos'!$C$338:$F$338,$J7),"")} -> 929.208 | AG7: {=IF(ISNUMBER($J7),IF($S7="Derreter",INDEX('Cálculos'!$C$124:$F$124,$J7)*(1+2.78*$AD7/($AD7+1400)+INDEX('Cálculos'!$C$122:$F$122,$J7)),IF($S7="Vaporizar",INDEX('Cálculos'!$C$125:$F$125,$J7)*(1+2.78*$AD7/($AD7+1400)+INDEX('Cálculos'!$C$123:$F$123,$J7)),1)),"")} -> 1 | AH7: =IF(ISNUMBER($J7),(($AC7*$N7+$AD7*$O7+$AE7*$P7+$AF7*$Q7)*$X7+$AL7)*$AG7,"") -> 33137.933 | AI7: {=IF(ISNUMBER($J7),$AH7*(1+INDEX('Cálculos'!$C$331:$F$331,$J7)),"")} -> 109951.66 | AJ7: {=IF(ISNUMBER($J7),$AH7*(1+MIN(INDEX('Cálculos'!$C$330:$F$330,$J7),1)*INDEX('Cálculos'!$C$331:$F$331,$J7)),"")} -> 109106.71 | AK7: =IF(ISNUMBER($J7),'Fixo (cálculo)'!$AF7,"") -> 0 | AL7: =IF(ISNUMBER($J7),$AK7*(1+$U7)*$V7*$W7,"") -> 0 | AN7: 8.2 s · c
A8: Mavuika - Habilidade: Flamestrider Sprint DMG | B8: 1 | C8: Nenhuma | D8: Todos | E8: -0.029 | F8: =IF($A8="","",IF(ISNUMBER(MATCH($A8,'Golpes extras'!$A$2:$A$101,0)),"Sim","Não")) -> Não | G8: {=IF($A8="","",IF($F8="Sim",INDEX('Golpes extras'!$B$2:$B$101,MATCH($A8,'Golpes extras'!$A$2:$A$101,0))&"",$A8))} -> Mavuika - Habilidade: Flamestrider Sprint DMG | H8: =IF($G8="","",IFERROR(MATCH($G8,L_Golpes!$A$2:$A$6000,0),"")) -> 51 | I8: {=IF($A8="","",IF(ISNUMBER($H8),INDEX(L_Golpes!$B$2:$B$6000,$H8),IF(IFERROR(INDEX('Golpes extras'!$C$2:$C$101,MATCH($A8,'Golpes extras'!$A$2:$A$101,0))&"","")<>"",INDEX('Golpes extras'!$C$2:$C$101,MATCH($A8,'Golpes extras'!$A$2:$A$101,0))&"","golpe?")))} -> Mavuika | J8: =IF(OR($I8="",$I8="golpe?"),"",IFERROR(MATCH($I8,Time!$B$4:$E$4,0),"fora do time")) -> 1 | K8: {=IF(ISNUMBER($J8),IF(IFERROR(INDEX('Golpes extras'!$D$2:$D$101,MATCH($A8,'Golpes extras'!$A$2:$A$101,0))&"","")<>"",INDEX('Golpes extras'!$D$2:$D$101,MATCH($A8,'Golpes extras'!$A$2:$A$101,0))&"",IF(ISNUMBER($H8),INDEX(L_Golpes!$D$2:$D$6000,$H8),"Outro")),"")} -> Habilidade | L8: {=IF(ISNUMBER($J8),IF(ISNUMBER($H8),INDEX(L_Golpes!$C$2:$C$6000,$H8),""),"")} -> Habilidade | M8: {=IF(ISNUMBER($J8),IF($L8="Normal",INDEX('Cálculos'!$C$14:$F$14,$J8),IF($L8="Habilidade",INDEX('Cálculos'!$C$15:$F$15,$J8),IF($L8="Supremo",INDEX('Cálculos'!$C$16:$F$16,$J8),""))),"")} -> 10 | N8: {=IF(ISNUMBER($J8),IF(ISNUMBER($H8),INDEX(L_Golpes!$F$2:$T$6000,$H8,MAX(1,MIN(15,$M8))),0)+IF($F8="Sim",N(INDEX('Golpes extras'!$E$2:$E$101,MATCH($A8,'Golpes extras'!$A$2:$A$101,0))),0),"")} -> 1.598 | O8: {=IF(ISNUMBER($J8),IF(ISNUMBER($H8),INDEX(L_Golpes!$U$2:$AI$6000,$H8,MAX(1,MIN(15,$M8))),0)+IF($F8="Sim",N(INDEX('Golpes extras'!$F$2:$F$101,MATCH($A8,'Golpes extras'!$A$2:$A$101,0))),0),"")} -> 0 | P8: {=IF(ISNUMBER($J8),IF(ISNUMBER($H8),INDEX(L_Golpes!$AJ$2:$AX$6000,$H8,MAX(1,MIN(15,$M8))),0)+IF($F8="Sim",N(INDEX('Golpes extras'!$G$2:$G$101,MATCH($A8,'Golpes extras'!$A$2:$A$101,0))),0),"")} -> 0 | Q8: {=IF(ISNUMBER($J8),IF(ISNUMBER($H8),INDEX(L_Golpes!$AY$2:$BM$6000,$H8,MAX(1,MIN(15,$M8))),0)+IF($F8="Sim",N(INDEX('Golpes extras'!$H$2:$H$101,MATCH($A8,'Golpes extras'!$A$2:$A$101,0))),0),"")} -> 0 | R8: {=IF(ISNUMBER($J8),INDEX('Cálculos'!$C$19:$F$19,$J8),"")} -> Pyro | S8: =IF(ISNUMBER($J8),IF(AND($C8="Derreter",OR($R8="Pyro",$R8="Cryo")),"Derreter",IF(AND($C8="Vaporizar",OR($R8="Pyro",$R8="Hydro")),"Vaporizar","Nenhuma")),"") -> Nenhuma | T8: =IF(ISNUMBER($J8),IF(OR($D8="Não",$D8=FALSE),'Perfis de buff'!$A$8,IF(OR($D8="",$D8="Sim",$D8=TRUE),'Perfis de buff'!$A$4,$D8)),"") -> Todos | U8: {=IF(ISNUMBER($J8),INDEX('Cálculos'!$C$113:$F$113,$J8)+IF($K8="Normal",INDEX('Cálculos'!$C$114:$F$114,$J8),IF($K8="Carregado",INDEX('Cálculos'!$C$115:$F$115,$J8),IF($K8="Habilidade",INDEX('Cálculos'!$C$116:$F$116,$J8),IF($K8="Supremo",INDEX('Cálculos'!$C$117:$F$117,$J8),0))))+INDEX('Cálculos'!$C$143:$F$147,IFERROR(MATCH($T8,'Perfis de buff'!$A$4:$A$8,0),1),$J8)+IF($K8="Normal",INDEX('Cálculos'!$C$148:$F$152,IFERROR(MATCH($T8,'Perfis de buff'!$A$4:$A$8,0),1),$J8),IF($K8="Carregado",INDEX('Cálculos'!$C$153:$F$157,IFERROR(MATCH($T8,'Perfis de buff'!$A$4:$A$8,0),1),$J8),IF($K8="Habilidade",INDEX('Cálculos'!$C$158:$F$162,IFERROR(MATCH($T8,'Perfis de buff'!$A$4:$A$8,0),1),$J8),IF($K8="Supremo",INDEX('Cálculos'!$C$163:$F$167,IFERROR(MATCH($T8,'Perfis de buff'!$A$4:$A$8,0),1),$J8),0))))+N($E8),"")} -> 1.787 | V8: {=IF(ISNUMBER($J8),INDEX('Cálculos'!$C$180:$F$180,$J8),"")} -> 0.48717949 | W8: {=IF(ISNUMBER($J8),INDEX('Cálculos'!$C$182:$F$182,$J8),"")} -> 1.05 | X8: =IF(ISNUMBER($J8),IF($B8="",1,$B8)*(1+$U8)*$V8*$W8,"") -> 1.4256577 | Y8: =IF(ISNUMBER($J8),$X8*$N8,"") -> 2.278201 | Z8: =IF(ISNUMBER($J8),$X8*$O8,"") -> 0 | AA8: =IF(ISNUMBER($J8),$X8*$P8,"") -> 0 | AB8: =IF(ISNUMBER($J8),$X8*$Q8,"") -> 0 | AC8: {=IF(ISNUMBER($J8),INDEX('Cálculos'!$C$332:$F$336,IFERROR(MATCH($T8,'Perfis de buff'!$A$4:$A$8,0),1),$J8),"")} -> 5791.25 | AD8: {=IF(ISNUMBER($J8),INDEX('Cálculos'!$C$339:$F$343,IFERROR(MATCH($T8,'Perfis de buff'!$A$4:$A$8,0),1),$J8),"")} -> 424 | AE8: {=IF(ISNUMBER($J8),INDEX('Cálculos'!$C$337:$F$337,$J8),"")} -> 19082.648 | AF8: {=IF(ISNUMBER($J8),INDEX('Cálculos'!$C$338:$F$338,$J8),"")} -> 929.208 | AG8: {=IF(ISNUMBER($J8),IF($S8="Derreter",INDEX('Cálculos'!$C$124:$F$124,$J8)*(1+2.78*$AD8/($AD8+1400)+INDEX('Cálculos'!$C$122:$F$122,$J8)),IF($S8="Vaporizar",INDEX('Cálculos'!$C$125:$F$125,$J8)*(1+2.78*$AD8/($AD8+1400)+INDEX('Cálculos'!$C$123:$F$123,$J8)),1)),"")} -> 1 | AH8: =IF(ISNUMBER($J8),(($AC8*$N8+$AD8*$O8+$AE8*$P8+$AF8*$Q8)*$X8+$AL8)*$AG8,"") -> 13193.631 | AI8: {=IF(ISNUMBER($J8),$AH8*(1+INDEX('Cálculos'!$C$331:$F$331,$J8)),"")} -> 43776.469 | AJ8: {=IF(ISNUMBER($J8),$AH8*(1+MIN(INDEX('Cálculos'!$C$330:$F$330,$J8),1)*INDEX('Cálculos'!$C$331:$F$331,$J8)),"")} -> 43440.058 | AK8: =IF(ISNUMBER($J8),'Fixo (cálculo)'!$AF8,"") -> 0 | AL8: =IF(ISNUMBER($J8),$AK8*(1+$U8)*$V8*$W8,"") -> 0 | AN8: 8.9 s · d
A9: Mavuika - Carregado no Supremo | B9: 1 | C9: Derreter | D9: Todos | E9: -0.042 | F9: =IF($A9="","",IF(ISNUMBER(MATCH($A9,'Golpes extras'!$A$2:$A$101,0)),"Sim","Não")) -> Sim | G9: {=IF($A9="","",IF($F9="Sim",INDEX('Golpes extras'!$B$2:$B$101,MATCH($A9,'Golpes extras'!$A$2:$A$101,0))&"",$A9))} -> Mavuika - Habilidade: Flamestrider Charged Attack Cyclic DMG | H9: =IF($G9="","",IFERROR(MATCH($G9,L_Golpes!$A$2:$A$6000,0),"")) -> 52 | I9: {=IF($A9="","",IF(ISNUMBER($H9),INDEX(L_Golpes!$B$2:$B$6000,$H9),IF(IFERROR(INDEX('Golpes extras'!$C$2:$C$101,MATCH($A9,'Golpes extras'!$A$2:$A$101,0))&"","")<>"",INDEX('Golpes extras'!$C$2:$C$101,MATCH($A9,'Golpes extras'!$A$2:$A$101,0))&"","golpe?")))} -> Mavuika | J9: =IF(OR($I9="",$I9="golpe?"),"",IFERROR(MATCH($I9,Time!$B$4:$E$4,0),"fora do time")) -> 1 | K9: {=IF(ISNUMBER($J9),IF(IFERROR(INDEX('Golpes extras'!$D$2:$D$101,MATCH($A9,'Golpes extras'!$A$2:$A$101,0))&"","")<>"",INDEX('Golpes extras'!$D$2:$D$101,MATCH($A9,'Golpes extras'!$A$2:$A$101,0))&"",IF(ISNUMBER($H9),INDEX(L_Golpes!$D$2:$D$6000,$H9),"Outro")),"")} -> Carregado | L9: {=IF(ISNUMBER($J9),IF(ISNUMBER($H9),INDEX(L_Golpes!$C$2:$C$6000,$H9),""),"")} -> Habilidade | M9: {=IF(ISNUMBER($J9),IF($L9="Normal",INDEX('Cálculos'!$C$14:$F$14,$J9),IF($L9="Habilidade",INDEX('Cálculos'!$C$15:$F$15,$J9),IF($L9="Supremo",INDEX('Cálculos'!$C$16:$F$16,$J9),""))),"")} -> 10 | N9: {=IF(ISNUMBER($J9),IF(ISNUMBER($H9),INDEX(L_Golpes!$F$2:$T$6000,$H9,MAX(1,MIN(15,$M9))),0)+IF($F9="Sim",N(INDEX('Golpes extras'!$E$2:$E$101,MATCH($A9,'Golpes extras'!$A$2:$A$101,0))),0),"")} -> 3.995 | O9: {=IF(ISNUMBER($J9),IF(ISNUMBER($H9),INDEX(L_Golpes!$U$2:$AI$6000,$H9,MAX(1,MIN(15,$M9))),0)+IF($F9="Sim",N(INDEX('Golpes extras'!$F$2:$F$101,MATCH($A9,'Golpes extras'!$A$2:$A$101,0))),0),"")} -> 0 | P9: {=IF(ISNUMBER($J9),IF(ISNUMBER($H9),INDEX(L_Golpes!$AJ$2:$AX$6000,$H9,MAX(1,MIN(15,$M9))),0)+IF($F9="Sim",N(INDEX('Golpes extras'!$G$2:$G$101,MATCH($A9,'Golpes extras'!$A$2:$A$101,0))),0),"")} -> 0 | Q9: {=IF(ISNUMBER($J9),IF(ISNUMBER($H9),INDEX(L_Golpes!$AY$2:$BM$6000,$H9,MAX(1,MIN(15,$M9))),0)+IF($F9="Sim",N(INDEX('Golpes extras'!$H$2:$H$101,MATCH($A9,'Golpes extras'!$A$2:$A$101,0))),0),"")} -> 0 | R9: {=IF(ISNUMBER($J9),INDEX('Cálculos'!$C$19:$F$19,$J9),"")} -> Pyro | S9: =IF(ISNUMBER($J9),IF(AND($C9="Derreter",OR($R9="Pyro",$R9="Cryo")),"Derreter",IF(AND($C9="Vaporizar",OR($R9="Pyro",$R9="Hydro")),"Vaporizar","Nenhuma")),"") -> Derreter | T9: =IF(ISNUMBER($J9),IF(OR($D9="Não",$D9=FALSE),'Perfis de buff'!$A$8,IF(OR($D9="",$D9="Sim",$D9=TRUE),'Perfis de buff'!$A$4,$D9)),"") -> Todos | U9: {=IF(ISNUMBER($J9),INDEX('Cálculos'!$C$113:$F$113,$J9)+IF($K9="Normal",INDEX('Cálculos'!$C$114:$F$114,$J9),IF($K9="Carregado",INDEX('Cálculos'!$C$115:$F$115,$J9),IF($K9="Habilidade",INDEX('Cálculos'!$C$116:$F$116,$J9),IF($K9="Supremo",INDEX('Cálculos'!$C$117:$F$117,$J9),0))))+INDEX('Cálculos'!$C$143:$F$147,IFERROR(MATCH($T9,'Perfis de buff'!$A$4:$A$8,0),1),$J9)+IF($K9="Normal",INDEX('Cálculos'!$C$148:$F$152,IFERROR(MATCH($T9,'Perfis de buff'!$A$4:$A$8,0),1),$J9),IF($K9="Carregado",INDEX('Cálculos'!$C$153:$F$157,IFERROR(MATCH($T9,'Perfis de buff'!$A$4:$A$8,0),1),$J9),IF($K9="Habilidade",INDEX('Cálculos'!$C$158:$F$162,IFERROR(MATCH($T9,'Perfis de buff'!$A$4:$A$8,0),1),$J9),IF($K9="Supremo",INDEX('Cálculos'!$C$163:$F$167,IFERROR(MATCH($T9,'Perfis de buff'!$A$4:$A$8,0),1),$J9),0))))+N($E9),"")} -> 1.774 | V9: {=IF(ISNUMBER($J9),INDEX('Cálculos'!$C$180:$F$180,$J9),"")} -> 0.48717949 | W9: {=IF(ISNUMBER($J9),INDEX('Cálculos'!$C$182:$F$182,$J9),"")} -> 1.05 | X9: =IF(ISNUMBER($J9),IF($B9="",1,$B9)*(1+$U9)*$V9*$W9,"") -> 1.4190077 | Y9: =IF(ISNUMBER($J9),$X9*$N9,"") -> 5.6689357 | Z9: =IF(ISNUMBER($J9),$X9*$O9,"") -> 0 | AA9: =IF(ISNUMBER($J9),$X9*$P9,"") -> 0 | AB9: =IF(ISNUMBER($J9),$X9*$Q9,"") -> 0 | AC9: {=IF(ISNUMBER($J9),INDEX('Cálculos'!$C$332:$F$336,IFERROR(MATCH($T9,'Perfis de buff'!$A$4:$A$8,0),1),$J9),"")} -> 5791.25 | AD9: {=IF(ISNUMBER($J9),INDEX('Cálculos'!$C$339:$F$343,IFERROR(MATCH($T9,'Perfis de buff'!$A$4:$A$8,0),1),$J9),"")} -> 424 | AE9: {=IF(ISNUMBER($J9),INDEX('Cálculos'!$C$337:$F$337,$J9),"")} -> 19082.648 | AF9: {=IF(ISNUMBER($J9),INDEX('Cálculos'!$C$338:$F$338,$J9),"")} -> 929.208 | AG9: {=IF(ISNUMBER($J9),IF($S9="Derreter",INDEX('Cálculos'!$C$124:$F$124,$J9)*(1+2.78*$AD9/($AD9+1400)+INDEX('Cálculos'!$C$122:$F$122,$J9)),IF($S9="Vaporizar",INDEX('Cálculos'!$C$125:$F$125,$J9)*(1+2.78*$AD9/($AD9+1400)+INDEX('Cálculos'!$C$123:$F$123,$J9)),1)),"")} -> 3.2924561 | AH9: =IF(ISNUMBER($J9),(($AC9*$N9+$AD9*$O9+$AE9*$P9+$AF9*$Q9)*$X9+$AL9)*$AG9,"") -> 108092.07 | AI9: {=IF(ISNUMBER($J9),$AH9*(1+INDEX('Cálculos'!$C$331:$F$331,$J9)),"")} -> 358649.5 | AJ9: {=IF(ISNUMBER($J9),$AH9*(1+MIN(INDEX('Cálculos'!$C$330:$F$330,$J9),1)*INDEX('Cálculos'!$C$331:$F$331,$J9)),"")} -> 355893.37 | AK9: =IF(ISNUMBER($J9),'Fixo (cálculo)'!$AF9,"") -> 0 | AL9: =IF(ISNUMBER($J9),$AK9*(1+$U9)*$V9*$W9,"") -> 0 | AN9: 9.5 s · C
A10: Mavuika - Carregado no Supremo | B10: 1 | C10: Nenhuma | D10: Todos | E10: -0.055 | F10: =IF($A10="","",IF(ISNUMBER(MATCH($A10,'Golpes extras'!$A$2:$A$101,0)),"Sim","Não")) -> Sim | G10: {=IF($A10="","",IF($F10="Sim",INDEX('Golpes extras'!$B$2:$B$101,MATCH($A10,'Golpes extras'!$A$2:$A$101,0))&"",$A10))} -> Mavuika - Habilidade: Flamestrider Charged Attack Cyclic DMG | H10: =IF($G10="","",IFERROR(MATCH($G10,L_Golpes!$A$2:$A$6000,0),"")) -> 52 | I10: {=IF($A10="","",IF(ISNUMBER($H10),INDEX(L_Golpes!$B$2:$B$6000,$H10),IF(IFERROR(INDEX('Golpes extras'!$C$2:$C$101,MATCH($A10,'Golpes extras'!$A$2:$A$101,0))&"","")<>"",INDEX('Golpes extras'!$C$2:$C$101,MATCH($A10,'Golpes extras'!$A$2:$A$101,0))&"","golpe?")))} -> Mavuika | J10: =IF(OR($I10="",$I10="golpe?"),"",IFERROR(MATCH($I10,Time!$B$4:$E$4,0),"fora do time")) -> 1 | K10: {=IF(ISNUMBER($J10),IF(IFERROR(INDEX('Golpes extras'!$D$2:$D$101,MATCH($A10,'Golpes extras'!$A$2:$A$101,0))&"","")<>"",INDEX('Golpes extras'!$D$2:$D$101,MATCH($A10,'Golpes extras'!$A$2:$A$101,0))&"",IF(ISNUMBER($H10),INDEX(L_Golpes!$D$2:$D$6000,$H10),"Outro")),"")} -> Carregado | L10: {=IF(ISNUMBER($J10),IF(ISNUMBER($H10),INDEX(L_Golpes!$C$2:$C$6000,$H10),""),"")} -> Habilidade | M10: {=IF(ISNUMBER($J10),IF($L10="Normal",INDEX('Cálculos'!$C$14:$F$14,$J10),IF($L10="Habilidade",INDEX('Cálculos'!$C$15:$F$15,$J10),IF($L10="Supremo",INDEX('Cálculos'!$C$16:$F$16,$J10),""))),"")} -> 10 | N10: {=IF(ISNUMBER($J10),IF(ISNUMBER($H10),INDEX(L_Golpes!$F$2:$T$6000,$H10,MAX(1,MIN(15,$M10))),0)+IF($F10="Sim",N(INDEX('Golpes extras'!$E$2:$E$101,MATCH($A10,'Golpes extras'!$A$2:$A$101,0))),0),"")} -> 3.995 | O10: {=IF(ISNUMBER($J10),IF(ISNUMBER($H10),INDEX(L_Golpes!$U$2:$AI$6000,$H10,MAX(1,MIN(15,$M10))),0)+IF($F10="Sim",N(INDEX('Golpes extras'!$F$2:$F$101,MATCH($A10,'Golpes extras'!$A$2:$A$101,0))),0),"")} -> 0 | P10: {=IF(ISNUMBER($J10),IF(ISNUMBER($H10),INDEX(L_Golpes!$AJ$2:$AX$6000,$H10,MAX(1,MIN(15,$M10))),0)+IF($F10="Sim",N(INDEX('Golpes extras'!$G$2:$G$101,MATCH($A10,'Golpes extras'!$A$2:$A$101,0))),0),"")} -> 0 | Q10: {=IF(ISNUMBER($J10),IF(ISNUMBER($H10),INDEX(L_Golpes!$AY$2:$BM$6000,$H10,MAX(1,MIN(15,$M10))),0)+IF($F10="Sim",N(INDEX('Golpes extras'!$H$2:$H$101,MATCH($A10,'Golpes extras'!$A$2:$A$101,0))),0),"")} -> 0 | R10: {=IF(ISNUMBER($J10),INDEX('Cálculos'!$C$19:$F$19,$J10),"")} -> Pyro | S10: =IF(ISNUMBER($J10),IF(AND($C10="Derreter",OR($R10="Pyro",$R10="Cryo")),"Derreter",IF(AND($C10="Vaporizar",OR($R10="Pyro",$R10="Hydro")),"Vaporizar","Nenhuma")),"") -> Nenhuma | T10: =IF(ISNUMBER($J10),IF(OR($D10="Não",$D10=FALSE),'Perfis de buff'!$A$8,IF(OR($D10="",$D10="Sim",$D10=TRUE),'Perfis de buff'!$A$4,$D10)),"") -> Todos | U10: {=IF(ISNUMBER($J10),INDEX('Cálculos'!$C$113:$F$113,$J10)+IF($K10="Normal",INDEX('Cálculos'!$C$114:$F$114,$J10),IF($K10="Carregado",INDEX('Cálculos'!$C$115:$F$115,$J10),IF($K10="Habilidade",INDEX('Cálculos'!$C$116:$F$116,$J10),IF($K10="Supremo",INDEX('Cálculos'!$C$117:$F$117,$J10),0))))+INDEX('Cálculos'!$C$143:$F$147,IFERROR(MATCH($T10,'Perfis de buff'!$A$4:$A$8,0),1),$J10)+IF($K10="Normal",INDEX('Cálculos'!$C$148:$F$152,IFERROR(MATCH($T10,'Perfis de buff'!$A$4:$A$8,0),1),$J10),IF($K10="Carregado",INDEX('Cálculos'!$C$153:$F$157,IFERROR(MATCH($T10,'Perfis de buff'!$A$4:$A$8,0),1),$J10),IF($K10="Habilidade",INDEX('Cálculos'!$C$158:$F$162,IFERROR(MATCH($T10,'Perfis de buff'!$A$4:$A$8,0),1),$J10),IF($K10="Supremo",INDEX('Cálculos'!$C$163:$F$167,IFERROR(MATCH($T10,'Perfis de buff'!$A$4:$A$8,0),1),$J10),0))))+N($E10),"")} -> 1.761 | V10: {=IF(ISNUMBER($J10),INDEX('Cálculos'!$C$180:$F$180,$J10),"")} -> 0.48717949 | W10: {=IF(ISNUMBER($J10),INDEX('Cálculos'!$C$182:$F$182,$J10),"")} -> 1.05 | X10: =IF(ISNUMBER($J10),IF($B10="",1,$B10)*(1+$U10)*$V10*$W10,"") -> 1.4123577 | Y10: =IF(ISNUMBER($J10),$X10*$N10,"") -> 5.642369 | Z10: =IF(ISNUMBER($J10),$X10*$O10,"") -> 0 | AA10: =IF(ISNUMBER($J10),$X10*$P10,"") -> 0 | AB10: =IF(ISNUMBER($J10),$X10*$Q10,"") -> 0 | AC10: {=IF(ISNUMBER($J10),INDEX('Cálculos'!$C$332:$F$336,IFERROR(MATCH($T10,'Perfis de buff'!$A$4:$A$8,0),1),$J10),"")} -> 5791.25 | AD10: {=IF(ISNUMBER($J10),INDEX('Cálculos'!$C$339:$F$343,IFERROR(MATCH($T10,'Perfis de buff'!$A$4:$A$8,0),1),$J10),"")} -> 424 | AE10: {=IF(ISNUMBER($J10),INDEX('Cálculos'!$C$337:$F$337,$J10),"")} -> 19082.648 | AF10: {=IF(ISNUMBER($J10),INDEX('Cálculos'!$C$338:$F$338,$J10),"")} -> 929.208 | AG10: {=IF(ISNUMBER($J10),IF($S10="Derreter",INDEX('Cálculos'!$C$124:$F$124,$J10)*(1+2.78*$AD10/($AD10+1400)+INDEX('Cálculos'!$C$122:$F$122,$J10)),IF($S10="Vaporizar",INDEX('Cálculos'!$C$125:$F$125,$J10)*(1+2.78*$AD10/($AD10+1400)+INDEX('Cálculos'!$C$123:$F$123,$J10)),1)),"")} -> 1 | AH10: =IF(ISNUMBER($J10),(($AC10*$N10+$AD10*$O10+$AE10*$P10+$AF10*$Q10)*$X10+$AL10)*$AG10,"") -> 32676.369 | AI10: {=IF(ISNUMBER($J10),$AH10*(1+INDEX('Cálculos'!$C$331:$F$331,$J10)),"")} -> 108420.19 | AJ10: {=IF(ISNUMBER($J10),$AH10*(1+MIN(INDEX('Cálculos'!$C$330:$F$330,$J10),1)*INDEX('Cálculos'!$C$331:$F$331,$J10)),"")} -> 107587.01 | AK10: =IF(ISNUMBER($J10),'Fixo (cálculo)'!$AF10,"") -> 0 | AL10: =IF(ISNUMBER($J10),$AK10*(1+$U10)*$V10*$W10,"") -> 0 | AN10: 10.2 s · c
A11: Mavuika - Carregado no Supremo | B11: 1 | C11: Nenhuma | D11: Todos | E11: -0.069 | F11: =IF($A11="","",IF(ISNUMBER(MATCH($A11,'Golpes extras'!$A$2:$A$101,0)),"Sim","Não")) -> Sim | G11: {=IF($A11="","",IF($F11="Sim",INDEX('Golpes extras'!$B$2:$B$101,MATCH($A11,'Golpes extras'!$A$2:$A$101,0))&"",$A11))} -> Mavuika - Habilidade: Flamestrider Charged Attack Cyclic DMG | H11: =IF($G11="","",IFERROR(MATCH($G11,L_Golpes!$A$2:$A$6000,0),"")) -> 52 | I11: {=IF($A11="","",IF(ISNUMBER($H11),INDEX(L_Golpes!$B$2:$B$6000,$H11),IF(IFERROR(INDEX('Golpes extras'!$C$2:$C$101,MATCH($A11,'Golpes extras'!$A$2:$A$101,0))&"","")<>"",INDEX('Golpes extras'!$C$2:$C$101,MATCH($A11,'Golpes extras'!$A$2:$A$101,0))&"","golpe?")))} -> Mavuika | J11: =IF(OR($I11="",$I11="golpe?"),"",IFERROR(MATCH($I11,Time!$B$4:$E$4,0),"fora do time")) -> 1 | K11: {=IF(ISNUMBER($J11),IF(IFERROR(INDEX('Golpes extras'!$D$2:$D$101,MATCH($A11,'Golpes extras'!$A$2:$A$101,0))&"","")<>"",INDEX('Golpes extras'!$D$2:$D$101,MATCH($A11,'Golpes extras'!$A$2:$A$101,0))&"",IF(ISNUMBER($H11),INDEX(L_Golpes!$D$2:$D$6000,$H11),"Outro")),"")} -> Carregado | L11: {=IF(ISNUMBER($J11),IF(ISNUMBER($H11),INDEX(L_Golpes!$C$2:$C$6000,$H11),""),"")} -> Habilidade | M11: {=IF(ISNUMBER($J11),IF($L11="Normal",INDEX('Cálculos'!$C$14:$F$14,$J11),IF($L11="Habilidade",INDEX('Cálculos'!$C$15:$F$15,$J11),IF($L11="Supremo",INDEX('Cálculos'!$C$16:$F$16,$J11),""))),"")} -> 10 | N11: {=IF(ISNUMBER($J11),IF(ISNUMBER($H11),INDEX(L_Golpes!$F$2:$T$6000,$H11,MAX(1,MIN(15,$M11))),0)+IF($F11="Sim",N(INDEX('Golpes extras'!$E$2:$E$101,MATCH($A11,'Golpes extras'!$A$2:$A$101,0))),0),"")} -> 3.995 | O11: {=IF(ISNUMBER($J11),IF(ISNUMBER($H11),INDEX(L_Golpes!$U$2:$AI$6000,$H11,MAX(1,MIN(15,$M11))),0)+IF($F11="Sim",N(INDEX('Golpes extras'!$F$2:$F$101,MATCH($A11,'Golpes extras'!$A$2:$A$101,0))),0),"")} -> 0 | P11: {=IF(ISNUMBER($J11),IF(ISNUMBER($H11),INDEX(L_Golpes!$AJ$2:$AX$6000,$H11,MAX(1,MIN(15,$M11))),0)+IF($F11="Sim",N(INDEX('Golpes extras'!$G$2:$G$101,MATCH($A11,'Golpes extras'!$A$2:$A$101,0))),0),"")} -> 0 | Q11: {=IF(ISNUMBER($J11),IF(ISNUMBER($H11),INDEX(L_Golpes!$AY$2:$BM$6000,$H11,MAX(1,MIN(15,$M11))),0)+IF($F11="Sim",N(INDEX('Golpes extras'!$H$2:$H$101,MATCH($A11,'Golpes extras'!$A$2:$A$101,0))),0),"")} -> 0 | R11: {=IF(ISNUMBER($J11),INDEX('Cálculos'!$C$19:$F$19,$J11),"")} -> Pyro | S11: =IF(ISNUMBER($J11),IF(AND($C11="Derreter",OR($R11="Pyro",$R11="Cryo")),"Derreter",IF(AND($C11="Vaporizar",OR($R11="Pyro",$R11="Hydro")),"Vaporizar","Nenhuma")),"") -> Nenhuma | T11: =IF(ISNUMBER($J11),IF(OR($D11="Não",$D11=FALSE),'Perfis de buff'!$A$8,IF(OR($D11="",$D11="Sim",$D11=TRUE),'Perfis de buff'!$A$4,$D11)),"") -> Todos | U11: {=IF(ISNUMBER($J11),INDEX('Cálculos'!$C$113:$F$113,$J11)+IF($K11="Normal",INDEX('Cálculos'!$C$114:$F$114,$J11),IF($K11="Carregado",INDEX('Cálculos'!$C$115:$F$115,$J11),IF($K11="Habilidade",INDEX('Cálculos'!$C$116:$F$116,$J11),IF($K11="Supremo",INDEX('Cálculos'!$C$117:$F$117,$J11),0))))+INDEX('Cálculos'!$C$143:$F$147,IFERROR(MATCH($T11,'Perfis de buff'!$A$4:$A$8,0),1),$J11)+IF($K11="Normal",INDEX('Cálculos'!$C$148:$F$152,IFERROR(MATCH($T11,'Perfis de buff'!$A$4:$A$8,0),1),$J11),IF($K11="Carregado",INDEX('Cálculos'!$C$153:$F$157,IFERROR(MATCH($T11,'Perfis de buff'!$A$4:$A$8,0),1),$J11),IF($K11="Habilidade",INDEX('Cálculos'!$C$158:$F$162,IFERROR(MATCH($T11,'Perfis de buff'!$A$4:$A$8,0),1),$J11),IF($K11="Supremo",INDEX('Cálculos'!$C$163:$F$167,IFERROR(MATCH($T11,'Perfis de buff'!$A$4:$A$8,0),1),$J11),0))))+N($E11),"")} -> 1.747 | V11: {=IF(ISNUMBER($J11),INDEX('Cálculos'!$C$180:$F$180,$J11),"")} -> 0.48717949 | W11: {=IF(ISNUMBER($J11),INDEX('Cálculos'!$C$182:$F$182,$J11),"")} -> 1.05 | X11: =IF(ISNUMBER($J11),IF($B11="",1,$B11)*(1+$U11)*$V11*$W11,"") -> 1.4051962 | Y11: =IF(ISNUMBER($J11),$X11*$N11,"") -> 5.6137586 | Z11: =IF(ISNUMBER($J11),$X11*$O11,"") -> 0 | AA11: =IF(ISNUMBER($J11),$X11*$P11,"") -> 0 | AB11: =IF(ISNUMBER($J11),$X11*$Q11,"") -> 0 | AC11: {=IF(ISNUMBER($J11),INDEX('Cálculos'!$C$332:$F$336,IFERROR(MATCH($T11,'Perfis de buff'!$A$4:$A$8,0),1),$J11),"")} -> 5791.25 | AD11: {=IF(ISNUMBER($J11),INDEX('Cálculos'!$C$339:$F$343,IFERROR(MATCH($T11,'Perfis de buff'!$A$4:$A$8,0),1),$J11),"")} -> 424 | AE11: {=IF(ISNUMBER($J11),INDEX('Cálculos'!$C$337:$F$337,$J11),"")} -> 19082.648 | AF11: {=IF(ISNUMBER($J11),INDEX('Cálculos'!$C$338:$F$338,$J11),"")} -> 929.208 | AG11: {=IF(ISNUMBER($J11),IF($S11="Derreter",INDEX('Cálculos'!$C$124:$F$124,$J11)*(1+2.78*$AD11/($AD11+1400)+INDEX('Cálculos'!$C$122:$F$122,$J11)),IF($S11="Vaporizar",INDEX('Cálculos'!$C$125:$F$125,$J11)*(1+2.78*$AD11/($AD11+1400)+INDEX('Cálculos'!$C$123:$F$123,$J11)),1)),"")} -> 1 | AH11: =IF(ISNUMBER($J11),(($AC11*$N11+$AD11*$O11+$AE11*$P11+$AF11*$Q11)*$X11+$AL11)*$AG11,"") -> 32510.68 | AI11: {=IF(ISNUMBER($J11),$AH11*(1+INDEX('Cálculos'!$C$331:$F$331,$J11)),"")} -> 107870.44 | AJ11: {=IF(ISNUMBER($J11),$AH11*(1+MIN(INDEX('Cálculos'!$C$330:$F$330,$J11),1)*INDEX('Cálculos'!$C$331:$F$331,$J11)),"")} -> 107041.48 | AK11: =IF(ISNUMBER($J11),'Fixo (cálculo)'!$AF11,"") -> 0 | AL11: =IF(ISNUMBER($J11),$AK11*(1+$U11)*$V11*$W11,"") -> 0 | AN11: 10.8 s · c
A12: Mavuika - Carregado final no Supremo | B12: 1 | C12: Derreter | D12: Todos | E12: -0.082 | F12: =IF($A12="","",IF(ISNUMBER(MATCH($A12,'Golpes extras'!$A$2:$A$101,0)),"Sim","Não")) -> Sim | G12: {=IF($A12="","",IF($F12="Sim",INDEX('Golpes extras'!$B$2:$B$101,MATCH($A12,'Golpes extras'!$A$2:$A$101,0))&"",$A12))} -> Mavuika - Habilidade: Flamestrider Charged Attack Final DMG | H12: =IF($G12="","",IFERROR(MATCH($G12,L_Golpes!$A$2:$A$6000,0),"")) -> 53 | I12: {=IF($A12="","",IF(ISNUMBER($H12),INDEX(L_Golpes!$B$2:$B$6000,$H12),IF(IFERROR(INDEX('Golpes extras'!$C$2:$C$101,MATCH($A12,'Golpes extras'!$A$2:$A$101,0))&"","")<>"",INDEX('Golpes extras'!$C$2:$C$101,MATCH($A12,'Golpes extras'!$A$2:$A$101,0))&"","golpe?")))} -> Mavuika | J12: =IF(OR($I12="",$I12="golpe?"),"",IFERROR(MATCH($I12,Time!$B$4:$E$4,0),"fora do time")) -> 1 | K12: {=IF(ISNUMBER($J12),IF(IFERROR(INDEX('Golpes extras'!$D$2:$D$101,MATCH($A12,'Golpes extras'!$A$2:$A$101,0))&"","")<>"",INDEX('Golpes extras'!$D$2:$D$101,MATCH($A12,'Golpes extras'!$A$2:$A$101,0))&"",IF(ISNUMBER($H12),INDEX(L_Golpes!$D$2:$D$6000,$H12),"Outro")),"")} -> Carregado | L12: {=IF(ISNUMBER($J12),IF(ISNUMBER($H12),INDEX(L_Golpes!$C$2:$C$6000,$H12),""),"")} -> Habilidade | M12: {=IF(ISNUMBER($J12),IF($L12="Normal",INDEX('Cálculos'!$C$14:$F$14,$J12),IF($L12="Habilidade",INDEX('Cálculos'!$C$15:$F$15,$J12),IF($L12="Supremo",INDEX('Cálculos'!$C$16:$F$16,$J12),""))),"")} -> 10 | N12: {=IF(ISNUMBER($J12),IF(ISNUMBER($H12),INDEX(L_Golpes!$F$2:$T$6000,$H12,MAX(1,MIN(15,$M12))),0)+IF($F12="Sim",N(INDEX('Golpes extras'!$E$2:$E$101,MATCH($A12,'Golpes extras'!$A$2:$A$101,0))),0),"")} -> 4.76 | O12: {=IF(ISNUMBER($J12),IF(ISNUMBER($H12),INDEX(L_Golpes!$U$2:$AI$6000,$H12,MAX(1,MIN(15,$M12))),0)+IF($F12="Sim",N(INDEX('Golpes extras'!$F$2:$F$101,MATCH($A12,'Golpes extras'!$A$2:$A$101,0))),0),"")} -> 0 | P12: {=IF(ISNUMBER($J12),IF(ISNUMBER($H12),INDEX(L_Golpes!$AJ$2:$AX$6000,$H12,MAX(1,MIN(15,$M12))),0)+IF($F12="Sim",N(INDEX('Golpes extras'!$G$2:$G$101,MATCH($A12,'Golpes extras'!$A$2:$A$101,0))),0),"")} -> 0 | Q12: {=IF(ISNUMBER($J12),IF(ISNUMBER($H12),INDEX(L_Golpes!$AY$2:$BM$6000,$H12,MAX(1,MIN(15,$M12))),0)+IF($F12="Sim",N(INDEX('Golpes extras'!$H$2:$H$101,MATCH($A12,'Golpes extras'!$A$2:$A$101,0))),0),"")} -> 0 | R12: {=IF(ISNUMBER($J12),INDEX('Cálculos'!$C$19:$F$19,$J12),"")} -> Pyro | S12: =IF(ISNUMBER($J12),IF(AND($C12="Derreter",OR($R12="Pyro",$R12="Cryo")),"Derreter",IF(AND($C12="Vaporizar",OR($R12="Pyro",$R12="Hydro")),"Vaporizar","Nenhuma")),"") -> Derreter | T12: =IF(ISNUMBER($J12),IF(OR($D12="Não",$D12=FALSE),'Perfis de buff'!$A$8,IF(OR($D12="",$D12="Sim",$D12=TRUE),'Perfis de buff'!$A$4,$D12)),"") -> Todos | U12: {=IF(ISNUMBER($J12),INDEX('Cálculos'!$C$113:$F$113,$J12)+IF($K12="Normal",INDEX('Cálculos'!$C$114:$F$114,$J12),IF($K12="Carregado",INDEX('Cálculos'!$C$115:$F$115,$J12),IF($K12="Habilidade",INDEX('Cálculos'!$C$116:$F$116,$J12),IF($K12="Supremo",INDEX('Cálculos'!$C$117:$F$117,$J12),0))))+INDEX('Cálculos'!$C$143:$F$147,IFERROR(MATCH($T12,'Perfis de buff'!$A$4:$A$8,0),1),$J12)+IF($K12="Normal",INDEX('Cálculos'!$C$148:$F$152,IFERROR(MATCH($T12,'Perfis de buff'!$A$4:$A$8,0),1),$J12),IF($K12="Carregado",INDEX('Cálculos'!$C$153:$F$157,IFERROR(MATCH($T12,'Perfis de buff'!$A$4:$A$8,0),1),$J12),IF($K12="Habilidade",INDEX('Cálculos'!$C$158:$F$162,IFERROR(MATCH($T12,'Perfis de buff'!$A$4:$A$8,0),1),$J12),IF($K12="Supremo",INDEX('Cálculos'!$C$163:$F$167,IFERROR(MATCH($T12,'Perfis de buff'!$A$4:$A$8,0),1),$J12),0))))+N($E12),"")} -> 1.734 | V12: {=IF(ISNUMBER($J12),INDEX('Cálculos'!$C$180:$F$180,$J12),"")} -> 0.48717949 | W12: {=IF(ISNUMBER($J12),INDEX('Cálculos'!$C$182:$F$182,$J12),"")} -> 1.05 | X12: =IF(ISNUMBER($J12),IF($B12="",1,$B12)*(1+$U12)*$V12*$W12,"") -> 1.3985462 | Y12: =IF(ISNUMBER($J12),$X12*$N12,"") -> 6.6570797 | Z12: =IF(ISNUMBER($J12),$X12*$O12,"") -> 0 | AA12: =IF(ISNUMBER($J12),$X12*$P12,"") -> 0 | AB12: =IF(ISNUMBER($J12),$X12*$Q12,"") -> 0 | AC12: {=IF(ISNUMBER($J12),INDEX('Cálculos'!$C$332:$F$336,IFERROR(MATCH($T12,'Perfis de buff'!$A$4:$A$8,0),1),$J12),"")} -> 5791.25 | AD12: {=IF(ISNUMBER($J12),INDEX('Cálculos'!$C$339:$F$343,IFERROR(MATCH($T12,'Perfis de buff'!$A$4:$A$8,0),1),$J12),"")} -> 424 | AE12: {=IF(ISNUMBER($J12),INDEX('Cálculos'!$C$337:$F$337,$J12),"")} -> 19082.648 | AF12: {=IF(ISNUMBER($J12),INDEX('Cálculos'!$C$338:$F$338,$J12),"")} -> 929.208 | AG12: {=IF(ISNUMBER($J12),IF($S12="Derreter",INDEX('Cálculos'!$C$124:$F$124,$J12)*(1+2.78*$AD12/($AD12+1400)+INDEX('Cálculos'!$C$122:$F$122,$J12)),IF($S12="Vaporizar",INDEX('Cálculos'!$C$125:$F$125,$J12)*(1+2.78*$AD12/($AD12+1400)+INDEX('Cálculos'!$C$123:$F$123,$J12)),1)),"")} -> 3.2924561 | AH12: =IF(ISNUMBER($J12),(($AC12*$N12+$AD12*$O12+$AE12*$P12+$AF12*$Q12)*$X12+$AL12)*$AG12,"") -> 126933.45 | AI12: {=IF(ISNUMBER($J12),$AH12*(1+INDEX('Cálculos'!$C$331:$F$331,$J12)),"")} -> 421165.17 | AJ12: {=IF(ISNUMBER($J12),$AH12*(1+MIN(INDEX('Cálculos'!$C$330:$F$330,$J12),1)*INDEX('Cálculos'!$C$331:$F$331,$J12)),"")} -> 417928.62 | AK12: =IF(ISNUMBER($J12),'Fixo (cálculo)'!$AF12,"") -> 0 | AL12: =IF(ISNUMBER($J12),$AK12*(1+$U12)*$V12*$W12,"") -> 0 | AN12: 11.5 s · F
A13: Mavuika - Habilidade: Flamestrider Sprint DMG | B13: 1 | C13: Nenhuma | D13: Todos | E13: -0.095 | F13: =IF($A13="","",IF(ISNUMBER(MATCH($A13,'Golpes extras'!$A$2:$A$101,0)),"Sim","Não")) -> Não | G13: {=IF($A13="","",IF($F13="Sim",INDEX('Golpes extras'!$B$2:$B$101,MATCH($A13,'Golpes extras'!$A$2:$A$101,0))&"",$A13))} -> Mavuika - Habilidade: Flamestrider Sprint DMG | H13: =IF($G13="","",IFERROR(MATCH($G13,L_Golpes!$A$2:$A$6000,0),"")) -> 51 | I13: {=IF($A13="","",IF(ISNUMBER($H13),INDEX(L_Golpes!$B$2:$B$6000,$H13),IF(IFERROR(INDEX('Golpes extras'!$C$2:$C$101,MATCH($A13,'Golpes extras'!$A$2:$A$101,0))&"","")<>"",INDEX('Golpes extras'!$C$2:$C$101,MATCH($A13,'Golpes extras'!$A$2:$A$101,0))&"","golpe?")))} -> Mavuika | J13: =IF(OR($I13="",$I13="golpe?"),"",IFERROR(MATCH($I13,Time!$B$4:$E$4,0),"fora do time")) -> 1 | K13: {=IF(ISNUMBER($J13),IF(IFERROR(INDEX('Golpes extras'!$D$2:$D$101,MATCH($A13,'Golpes extras'!$A$2:$A$101,0))&"","")<>"",INDEX('Golpes extras'!$D$2:$D$101,MATCH($A13,'Golpes extras'!$A$2:$A$101,0))&"",IF(ISNUMBER($H13),INDEX(L_Golpes!$D$2:$D$6000,$H13),"Outro")),"")} -> Habilidade | L13: {=IF(ISNUMBER($J13),IF(ISNUMBER($H13),INDEX(L_Golpes!$C$2:$C$6000,$H13),""),"")} -> Habilidade | M13: {=IF(ISNUMBER($J13),IF($L13="Normal",INDEX('Cálculos'!$C$14:$F$14,$J13),IF($L13="Habilidade",INDEX('Cálculos'!$C$15:$F$15,$J13),IF($L13="Supremo",INDEX('Cálculos'!$C$16:$F$16,$J13),""))),"")} -> 10 | N13: {=IF(ISNUMBER($J13),IF(ISNUMBER($H13),INDEX(L_Golpes!$F$2:$T$6000,$H13,MAX(1,MIN(15,$M13))),0)+IF($F13="Sim",N(INDEX('Golpes extras'!$E$2:$E$101,MATCH($A13,'Golpes extras'!$A$2:$A$101,0))),0),"")} -> 1.598 | O13: {=IF(ISNUMBER($J13),IF(ISNUMBER($H13),INDEX(L_Golpes!$U$2:$AI$6000,$H13,MAX(1,MIN(15,$M13))),0)+IF($F13="Sim",N(INDEX('Golpes extras'!$F$2:$F$101,MATCH($A13,'Golpes extras'!$A$2:$A$101,0))),0),"")} -> 0 | P13: {=IF(ISNUMBER($J13),IF(ISNUMBER($H13),INDEX(L_Golpes!$AJ$2:$AX$6000,$H13,MAX(1,MIN(15,$M13))),0)+IF($F13="Sim",N(INDEX('Golpes extras'!$G$2:$G$101,MATCH($A13,'Golpes extras'!$A$2:$A$101,0))),0),"")} -> 0 | Q13: {=IF(ISNUMBER($J13),IF(ISNUMBER($H13),INDEX(L_Golpes!$AY$2:$BM$6000,$H13,MAX(1,MIN(15,$M13))),0)+IF($F13="Sim",N(INDEX('Golpes extras'!$H$2:$H$101,MATCH($A13,'Golpes extras'!$A$2:$A$101,0))),0),"")} -> 0 | R13: {=IF(ISNUMBER($J13),INDEX('Cálculos'!$C$19:$F$19,$J13),"")} -> Pyro | S13: =IF(ISNUMBER($J13),IF(AND($C13="Derreter",OR($R13="Pyro",$R13="Cryo")),"Derreter",IF(AND($C13="Vaporizar",OR($R13="Pyro",$R13="Hydro")),"Vaporizar","Nenhuma")),"") -> Nenhuma | T13: =IF(ISNUMBER($J13),IF(OR($D13="Não",$D13=FALSE),'Perfis de buff'!$A$8,IF(OR($D13="",$D13="Sim",$D13=TRUE),'Perfis de buff'!$A$4,$D13)),"") -> Todos | U13: {=IF(ISNUMBER($J13),INDEX('Cálculos'!$C$113:$F$113,$J13)+IF($K13="Normal",INDEX('Cálculos'!$C$114:$F$114,$J13),IF($K13="Carregado",INDEX('Cálculos'!$C$115:$F$115,$J13),IF($K13="Habilidade",INDEX('Cálculos'!$C$116:$F$116,$J13),IF($K13="Supremo",INDEX('Cálculos'!$C$117:$F$117,$J13),0))))+INDEX('Cálculos'!$C$143:$F$147,IFERROR(MATCH($T13,'Perfis de buff'!$A$4:$A$8,0),1),$J13)+IF($K13="Normal",INDEX('Cálculos'!$C$148:$F$152,IFERROR(MATCH($T13,'Perfis de buff'!$A$4:$A$8,0),1),$J13),IF($K13="Carregado",INDEX('Cálculos'!$C$153:$F$157,IFERROR(MATCH($T13,'Perfis de buff'!$A$4:$A$8,0),1),$J13),IF($K13="Habilidade",INDEX('Cálculos'!$C$158:$F$162,IFERROR(MATCH($T13,'Perfis de buff'!$A$4:$A$8,0),1),$J13),IF($K13="Supremo",INDEX('Cálculos'!$C$163:$F$167,IFERROR(MATCH($T13,'Perfis de buff'!$A$4:$A$8,0),1),$J13),0))))+N($E13),"")} -> 1.721 | V13: {=IF(ISNUMBER($J13),INDEX('Cálculos'!$C$180:$F$180,$J13),"")} -> 0.48717949 | W13: {=IF(ISNUMBER($J13),INDEX('Cálculos'!$C$182:$F$182,$J13),"")} -> 1.05 | X13: =IF(ISNUMBER($J13),IF($B13="",1,$B13)*(1+$U13)*$V13*$W13,"") -> 1.3918962 | Y13: =IF(ISNUMBER($J13),$X13*$N13,"") -> 2.2242501 | Z13: =IF(ISNUMBER($J13),$X13*$O13,"") -> 0 | AA13: =IF(ISNUMBER($J13),$X13*$P13,"") -> 0 | AB13: =IF(ISNUMBER($J13),$X13*$Q13,"") -> 0 | AC13: {=IF(ISNUMBER($J13),INDEX('Cálculos'!$C$332:$F$336,IFERROR(MATCH($T13,'Perfis de buff'!$A$4:$A$8,0),1),$J13),"")} -> 5791.25 | AD13: {=IF(ISNUMBER($J13),INDEX('Cálculos'!$C$339:$F$343,IFERROR(MATCH($T13,'Perfis de buff'!$A$4:$A$8,0),1),$J13),"")} -> 424 | AE13: {=IF(ISNUMBER($J13),INDEX('Cálculos'!$C$337:$F$337,$J13),"")} -> 19082.648 | AF13: {=IF(ISNUMBER($J13),INDEX('Cálculos'!$C$338:$F$338,$J13),"")} -> 929.208 | AG13: {=IF(ISNUMBER($J13),IF($S13="Derreter",INDEX('Cálculos'!$C$124:$F$124,$J13)*(1+2.78*$AD13/($AD13+1400)+INDEX('Cálculos'!$C$122:$F$122,$J13)),IF($S13="Vaporizar",INDEX('Cálculos'!$C$125:$F$125,$J13)*(1+2.78*$AD13/($AD13+1400)+INDEX('Cálculos'!$C$123:$F$123,$J13)),1)),"")} -> 1 | AH13: =IF(ISNUMBER($J13),(($AC13*$N13+$AD13*$O13+$AE13*$P13+$AF13*$Q13)*$X13+$AL13)*$AG13,"") -> 12881.188 | AI13: {=IF(ISNUMBER($J13),$AH13*(1+INDEX('Cálculos'!$C$331:$F$331,$J13)),"")} -> 42739.782 | AJ13: {=IF(ISNUMBER($J13),$AH13*(1+MIN(INDEX('Cálculos'!$C$330:$F$330,$J13),1)*INDEX('Cálculos'!$C$331:$F$331,$J13)),"")} -> 42411.338 | AK13: =IF(ISNUMBER($J13),'Fixo (cálculo)'!$AF13,"") -> 0 | AL13: =IF(ISNUMBER($J13),$AK13*(1+$U13)*$V13*$W13,"") -> 0 | AN13: 12.1 s · [d
A14: Mavuika - Carregado no Supremo | B14: 1 | C14: Nenhuma | D14: Todos | E14: -0.108 | F14: =IF($A14="","",IF(ISNUMBER(MATCH($A14,'Golpes extras'!$A$2:$A$101,0)),"Sim","Não")) -> Sim | G14: {=IF($A14="","",IF($F14="Sim",INDEX('Golpes extras'!$B$2:$B$101,MATCH($A14,'Golpes extras'!$A$2:$A$101,0))&"",$A14))} -> Mavuika - Habilidade: Flamestrider Charged Attack Cyclic DMG | H14: =IF($G14="","",IFERROR(MATCH($G14,L_Golpes!$A$2:$A$6000,0),"")) -> 52 | I14: {=IF($A14="","",IF(ISNUMBER($H14),INDEX(L_Golpes!$B$2:$B$6000,$H14),IF(IFERROR(INDEX('Golpes extras'!$C$2:$C$101,MATCH($A14,'Golpes extras'!$A$2:$A$101,0))&"","")<>"",INDEX('Golpes extras'!$C$2:$C$101,MATCH($A14,'Golpes extras'!$A$2:$A$101,0))&"","golpe?")))} -> Mavuika | J14: =IF(OR($I14="",$I14="golpe?"),"",IFERROR(MATCH($I14,Time!$B$4:$E$4,0),"fora do time")) -> 1 | K14: {=IF(ISNUMBER($J14),IF(IFERROR(INDEX('Golpes extras'!$D$2:$D$101,MATCH($A14,'Golpes extras'!$A$2:$A$101,0))&"","")<>"",INDEX('Golpes extras'!$D$2:$D$101,MATCH($A14,'Golpes extras'!$A$2:$A$101,0))&"",IF(ISNUMBER($H14),INDEX(L_Golpes!$D$2:$D$6000,$H14),"Outro")),"")} -> Carregado | L14: {=IF(ISNUMBER($J14),IF(ISNUMBER($H14),INDEX(L_Golpes!$C$2:$C$6000,$H14),""),"")} -> Habilidade | M14: {=IF(ISNUMBER($J14),IF($L14="Normal",INDEX('Cálculos'!$C$14:$F$14,$J14),IF($L14="Habilidade",INDEX('Cálculos'!$C$15:$F$15,$J14),IF($L14="Supremo",INDEX('Cálculos'!$C$16:$F$16,$J14),""))),"")} -> 10 | N14: {=IF(ISNUMBER($J14),IF(ISNUMBER($H14),INDEX(L_Golpes!$F$2:$T$6000,$H14,MAX(1,MIN(15,$M14))),0)+IF($F14="Sim",N(INDEX('Golpes extras'!$E$2:$E$101,MATCH($A14,'Golpes extras'!$A$2:$A$101,0))),0),"")} -> 3.995 | O14: {=IF(ISNUMBER($J14),IF(ISNUMBER($H14),INDEX(L_Golpes!$U$2:$AI$6000,$H14,MAX(1,MIN(15,$M14))),0)+IF($F14="Sim",N(INDEX('Golpes extras'!$F$2:$F$101,MATCH($A14,'Golpes extras'!$A$2:$A$101,0))),0),"")} -> 0 | P14: {=IF(ISNUMBER($J14),IF(ISNUMBER($H14),INDEX(L_Golpes!$AJ$2:$AX$6000,$H14,MAX(1,MIN(15,$M14))),0)+IF($F14="Sim",N(INDEX('Golpes extras'!$G$2:$G$101,MATCH($A14,'Golpes extras'!$A$2:$A$101,0))),0),"")} -> 0 | Q14: {=IF(ISNUMBER($J14),IF(ISNUMBER($H14),INDEX(L_Golpes!$AY$2:$BM$6000,$H14,MAX(1,MIN(15,$M14))),0)+IF($F14="Sim",N(INDEX('Golpes extras'!$H$2:$H$101,MATCH($A14,'Golpes extras'!$A$2:$A$101,0))),0),"")} -> 0 | R14: {=IF(ISNUMBER($J14),INDEX('Cálculos'!$C$19:$F$19,$J14),"")} -> Pyro | S14: =IF(ISNUMBER($J14),IF(AND($C14="Derreter",OR($R14="Pyro",$R14="Cryo")),"Derreter",IF(AND($C14="Vaporizar",OR($R14="Pyro",$R14="Hydro")),"Vaporizar","Nenhuma")),"") -> Nenhuma | T14: =IF(ISNUMBER($J14),IF(OR($D14="Não",$D14=FALSE),'Perfis de buff'!$A$8,IF(OR($D14="",$D14="Sim",$D14=TRUE),'Perfis de buff'!$A$4,$D14)),"") -> Todos | U14: {=IF(ISNUMBER($J14),INDEX('Cálculos'!$C$113:$F$113,$J14)+IF($K14="Normal",INDEX('Cálculos'!$C$114:$F$114,$J14),IF($K14="Carregado",INDEX('Cálculos'!$C$115:$F$115,$J14),IF($K14="Habilidade",INDEX('Cálculos'!$C$116:$F$116,$J14),IF($K14="Supremo",INDEX('Cálculos'!$C$117:$F$117,$J14),0))))+INDEX('Cálculos'!$C$143:$F$147,IFERROR(MATCH($T14,'Perfis de buff'!$A$4:$A$8,0),1),$J14)+IF($K14="Normal",INDEX('Cálculos'!$C$148:$F$152,IFERROR(MATCH($T14,'Perfis de buff'!$A$4:$A$8,0),1),$J14),IF($K14="Carregado",INDEX('Cálculos'!$C$153:$F$157,IFERROR(MATCH($T14,'Perfis de buff'!$A$4:$A$8,0),1),$J14),IF($K14="Habilidade",INDEX('Cálculos'!$C$158:$F$162,IFERROR(MATCH($T14,'Perfis de buff'!$A$4:$A$8,0),1),$J14),IF($K14="Supremo",INDEX('Cálculos'!$C$163:$F$167,IFERROR(MATCH($T14,'Perfis de buff'!$A$4:$A$8,0),1),$J14),0))))+N($E14),"")} -> 1.708 | V14: {=IF(ISNUMBER($J14),INDEX('Cálculos'!$C$180:$F$180,$J14),"")} -> 0.48717949 | W14: {=IF(ISNUMBER($J14),INDEX('Cálculos'!$C$182:$F$182,$J14),"")} -> 1.05 | X14: =IF(ISNUMBER($J14),IF($B14="",1,$B14)*(1+$U14)*$V14*$W14,"") -> 1.3852462 | Y14: =IF(ISNUMBER($J14),$X14*$N14,"") -> 5.5340584 | Z14: =IF(ISNUMBER($J14),$X14*$O14,"") -> 0 | AA14: =IF(ISNUMBER($J14),$X14*$P14,"") -> 0 | AB14: =IF(ISNUMBER($J14),$X14*$Q14,"") -> 0 | AC14: {=IF(ISNUMBER($J14),INDEX('Cálculos'!$C$332:$F$336,IFERROR(MATCH($T14,'Perfis de buff'!$A$4:$A$8,0),1),$J14),"")} -> 5791.25 | AD14: {=IF(ISNUMBER($J14),INDEX('Cálculos'!$C$339:$F$343,IFERROR(MATCH($T14,'Perfis de buff'!$A$4:$A$8,0),1),$J14),"")} -> 424 | AE14: {=IF(ISNUMBER($J14),INDEX('Cálculos'!$C$337:$F$337,$J14),"")} -> 19082.648 | AF14: {=IF(ISNUMBER($J14),INDEX('Cálculos'!$C$338:$F$338,$J14),"")} -> 929.208 | AG14: {=IF(ISNUMBER($J14),IF($S14="Derreter",INDEX('Cálculos'!$C$124:$F$124,$J14)*(1+2.78*$AD14/($AD14+1400)+INDEX('Cálculos'!$C$122:$F$122,$J14)),IF($S14="Vaporizar",INDEX('Cálculos'!$C$125:$F$125,$J14)*(1+2.78*$AD14/($AD14+1400)+INDEX('Cálculos'!$C$123:$F$123,$J14)),1)),"")} -> 1 | AH14: =IF(ISNUMBER($J14),(($AC14*$N14+$AD14*$O14+$AE14*$P14+$AF14*$Q14)*$X14+$AL14)*$AG14,"") -> 32049.116 | AI14: {=IF(ISNUMBER($J14),$AH14*(1+INDEX('Cálculos'!$C$331:$F$331,$J14)),"")} -> 106338.97 | AJ14: {=IF(ISNUMBER($J14),$AH14*(1+MIN(INDEX('Cálculos'!$C$330:$F$330,$J14),1)*INDEX('Cálculos'!$C$331:$F$331,$J14)),"")} -> 105521.78 | AK14: =IF(ISNUMBER($J14),'Fixo (cálculo)'!$AF14,"") -> 0 | AL14: =IF(ISNUMBER($J14),$AK14*(1+$U14)*$V14*$W14,"") -> 0 | AN14: 12.8 s · c
